<?xml version="1.0" ?>
<robot name="ppp90" xmlns:xacro="http://www.ros.org/wiki/xacro">

<xacro:include filename="$(find ppp90_description)/urdf/materials.xacro" />
<xacro:include filename="$(find ppp90_description)/urdf/ppp90.trans" />
<xacro:include filename="$(find ppp90_description)/urdf/ppp90.gazebo" />

<link name="base_footprint"/>

<joint name="base_joint" type="fixed">
    <parent link="base_footprint"/>
    <child link="base_link"/>
    <origin xyz="0.0 0.0 0.010" rpy="0 0 0"/>
</joint>

<link name="base_link">
  <visual>
    <origin rpy="0 0 0" xyz="0 0 0"/>
    <geometry>
      <mesh filename="package://ppp90_description/meshes/base_link.stl" scale="0.001 0.001 0.001"/>
    </geometry>
    <material name="silver"/>
  </visual>
  <collision>
    <origin rpy="0 0 0" xyz="0 0 0"/>
    <geometry>
      <mesh filename="package://ppp90_description/meshes/base_link.stl" scale="0.001 0.001 0.001"/>
    </geometry>
  </collision>
</link>

<link name="wheel_1">
  <inertial>
    <origin rpy="0 0 0" xyz="-6.348907630078851e-05 -0.01199981164843078 -0.00029175072703385013"/>
    <mass value="0.7647072407364309"/>
    <inertia ixx="0.000285" ixy="-0.0" ixz="0.0" iyy="0.000502" iyz="0.0" izz="0.000285"/>
  </inertial>
  <visual>
    <origin rpy="0 0 0" xyz="0.014494 -0.129921 -0.024125"/>
    <geometry>
      <mesh filename="package://ppp90_description/meshes/wheel_1.stl" scale="0.001 0.001 0.001"/>
    </geometry>
    <material name="silver"/>
  </visual>
  <collision>
    <origin rpy="0 0 0" xyz="0.014494 -0.129921 -0.024125"/>
    <geometry>
      <mesh filename="package://ppp90_description/meshes/wheel_1.stl" scale="0.001 0.001 0.001"/>
    </geometry>
  </collision>
</link>

<link name="wheel_Mirror__1">
  <inertial>
    <origin rpy="0 0 0" xyz="0.0001513902914462642 -0.011999864080914024 0.00026807201904406955"/>
    <mass value="0.7647072407364308"/>
    <inertia ixx="0.000285" ixy="-0.0" ixz="0.0" iyy="0.000502" iyz="0.0" izz="0.000285"/>
  </inertial>
  <visual>
    <origin rpy="0 0 0" xyz="0.014491 0.136188 -0.024125"/>
    <geometry>
      <mesh filename="package://ppp90_description/meshes/wheel_Mirror__1.stl" scale="0.001 0.001 0.001"/>
    </geometry>
    <material name="silver"/>
  </visual>
  <collision>
    <origin rpy="0 0 0" xyz="0.014491 0.136188 -0.024125"/>
    <geometry>
      <mesh filename="package://ppp90_description/meshes/wheel_Mirror__1.stl" scale="0.001 0.001 0.001"/>
    </geometry>
  </collision>
</link>

<link name="sonyc_1">
  <inertial>
    <origin rpy="0 0 0" xyz="0.013000365548618742 -0.010235515019977243 5.0631813087009814e-05"/>
    <mass value="0.0252883585593009"/>
    <inertia ixx="1e-06" ixy="0.0" ixz="0.0" iyy="5e-06" iyz="-0.0" izz="5e-06"/>
  </inertial>
  <visual>
    <origin rpy="0 0 0" xyz="0.027494 -0.13623 -0.08983"/>
    <geometry>
      <box size="0.001 0.0005 0.00035"/>
      <!-- <mesh filename="package://ppp90_description/meshes/sonyc_1.stl" scale="0.001 0.001 0.001"/> -->
    </geometry>
    <material name="silver"/>
  </visual>
  <!-- <collision>
    <origin rpy="0 0 0" xyz="0.027494 -0.13623 -0.08983"/>
    <geometry>
      <mesh filename="package://ppp90_description/meshes/sonyc_1.stl" scale="0.001 0.001 0.001"/>
    </geometry>
  </collision> -->
</link>

<link name="sonyc_Mirror__1">
  <inertial>
    <origin rpy="0 0 0" xyz="-0.012999634451381028 0.010235325598471623 5.063181308698206e-05"/>
    <mass value="0.025288358559300887"/>
    <inertia ixx="1e-06" ixy="-0.0" ixz="0.0" iyy="5e-06" iyz="0.0" izz="5e-06"/>
  </inertial>
  <visual>
    <origin rpy="0 0 0" xyz="0.001494 0.164906 -0.08983"/>
    <geometry>
      <box size="0.001 0.0005 0.00035"/>
      <!-- <mesh filename="package://ppp90_description/meshes/sonyc_Mirror__1.stl" scale="0.001 0.001 0.001"/> -->
    </geometry>
    <material name="silver"/>
  </visual>
  <!-- <collision>
    <origin rpy="0 0 0" xyz="0.001494 0.164906 -0.08983"/>
    <geometry>
      <mesh filename="package://ppp90_description/meshes/sonyc_Mirror__1.stl" scale="0.001 0.001 0.001"/>
    </geometry>
  </collision> -->
</link>

<link name="sonyc__1__1">
  <inertial>
    <origin rpy="0 0 0" xyz="0.010235448068739439 -0.013000419106913505 5.063181308698206e-05"/>
    <mass value="0.0252883585593009"/>
    <inertia ixx="5e-06" ixy="-0.0" ixz="0.0" iyy="1e-06" iyz="0.0" izz="5e-06"/>
  </inertial>
  <visual>
    <origin rpy="0 0 0" xyz="0.169414 0.001361 -0.06983"/>
    <geometry>
      <box size="0.001 0.0005 0.00035"/>
      <!-- <mesh filename="package://ppp90_description/meshes/sonyc__1__1.stl" scale="0.001 0.001 0.001"/> -->
    </geometry>
    <material name="silver"/>
  </visual>
  <!-- <collision>
    <origin rpy="0 0 0" xyz="0.169414 0.001361 -0.06983"/>
    <geometry>
      <mesh filename="package://ppp90_description/meshes/sonyc__1__1.stl" scale="0.001 0.001 0.001"/>
    </geometry>
  </collision> -->
</link>

<link name="nema17_1">
  <inertial>
    <origin rpy="0 0 0" xyz="-6.709208478471174e-07 -0.00334258185473002 0.02118013525930306"/>
    <mass value="0.1838412954712099"/>
    <inertia ixx="5.2e-05" ixy="-0.0" ixz="-0.0" iyy="5.3e-05" iyz="0.0" izz="5.2e-05"/>
  </inertial>
  <visual>
    <origin rpy="0 0 0" xyz="0.014494 -0.084071 -0.003"/>
    <geometry>
      <mesh filename="package://ppp90_description/meshes/nema17_1.stl" scale="0.001 0.001 0.001"/>
    </geometry>
    <material name="silver"/>
  </visual>
  <collision>
    <origin rpy="0 0 0" xyz="0.014494 -0.084071 -0.003"/>
    <geometry>
      <mesh filename="package://ppp90_description/meshes/nema17_1.stl" scale="0.001 0.001 0.001"/>
    </geometry>
  </collision>
</link>

<link name="nema17_Mirror__1">
  <inertial>
    <origin rpy="0 0 0" xyz="-5.975012162888829e-06 0.00334264208445903 0.02118013525930306"/>
    <mass value="0.1838412954712099"/>
    <inertia ixx="5.2e-05" ixy="-0.0" ixz="-0.0" iyy="5.3e-05" iyz="-0.0" izz="5.2e-05"/>
  </inertial>
  <visual>
    <origin rpy="0 0 0" xyz="0.014528 0.113338 -0.003"/>
    <geometry>
      <mesh filename="package://ppp90_description/meshes/nema17_Mirror__1.stl" scale="0.001 0.001 0.001"/>
    </geometry>
    <material name="silver"/>
  </visual>
  <collision>
    <origin rpy="0 0 0" xyz="0.014528 0.113338 -0.003"/>
    <geometry>
      <mesh filename="package://ppp90_description/meshes/nema17_Mirror__1.stl" scale="0.001 0.001 0.001"/>
    </geometry>
  </collision>
</link>

<link name="12GAN20__1__1">
  <inertial>
    <origin rpy="0 0 0" xyz="3.268980405812805e-08 -3.387342204674848e-06 0.011857871337072723"/>
    <mass value="0.023492103087793172"/>
    <inertia ixx="1e-06" ixy="-0.0" ixz="-0.0" iyy="2e-06" iyz="-0.0" izz="0.0"/>
  </inertial>
  <visual>
    <origin rpy="0 0 0" xyz="0.096453 0.12774 -0.001"/>
    <geometry>
      <mesh filename="package://ppp90_description/meshes/12GAN20__1__1.stl" scale="0.001 0.001 0.001"/>
    </geometry>
    <material name="silver"/>
  </visual>
  <collision>
    <origin rpy="0 0 0" xyz="0.096453 0.12774 -0.001"/>
    <geometry>
      <mesh filename="package://ppp90_description/meshes/12GAN20__1__1.stl" scale="0.001 0.001 0.001"/>
    </geometry>
  </collision>
</link>

<link name="brush_1">
  <inertial>
    <origin rpy="0 0 0" xyz="-6.629561645765669e-07 -8.680417363238213e-07 -0.0022204199308318013"/>
    <mass value="0.014937067448072668"/>
    <inertia ixx="1e-06" ixy="0.0" ixz="0.0" iyy="1e-06" iyz="0.0" izz="2e-06"/>
  </inertial>
  <visual>
    <origin rpy="0 0 0" xyz="0.096455 0.12775 0.001"/>
    <geometry>
      <mesh filename="package://ppp90_description/meshes/brush_1.stl" scale="0.001 0.001 0.001"/>
    </geometry>
    <material name="silver"/>
  </visual>
  <collision>
    <origin rpy="0 0 0" xyz="0.096455 0.12775 0.001"/>
    <geometry>
      <mesh filename="package://ppp90_description/meshes/brush_1.stl" scale="0.001 0.001 0.001"/>
    </geometry>
  </collision>
</link>

<link name="brush_Mirror__1">
  <inertial>
    <origin rpy="0 0 0" xyz="5.998655124295205e-07 3.438472244571278e-07 -0.0022204199308317827"/>
    <mass value="0.014937067448072664"/>
    <inertia ixx="1e-06" ixy="0.0" ixz="-0.0" iyy="1e-06" iyz="0.0" izz="2e-06"/>
  </inertial>
  <visual>
    <origin rpy="0 0 0" xyz="0.096451 -0.099054 0.001"/>
    <geometry>
      <mesh filename="package://ppp90_description/meshes/brush_Mirror__1.stl" scale="0.001 0.001 0.001"/>
    </geometry>
    <material name="silver"/>
  </visual>
  <collision>
    <origin rpy="0 0 0" xyz="0.096451 -0.099054 0.001"/>
    <geometry>
      <mesh filename="package://ppp90_description/meshes/brush_Mirror__1.stl" scale="0.001 0.001 0.001"/>
    </geometry>
  </collision>
</link>

<link name="12GAN20__1__Mirror__1">
  <inertial>
    <origin rpy="0 0 0" xyz="2.061205277625877e-06 -6.450130101642859e-06 0.011857871337072723"/>
    <mass value="0.02349210308779317"/>
    <inertia ixx="1e-06" ixy="0.0" ixz="-0.0" iyy="2e-06" iyz="0.0" izz="0.0"/>
  </inertial>
  <visual>
    <origin rpy="0 0 0" xyz="0.096451 -0.099054 -0.001"/>
    <geometry>
      <mesh filename="package://ppp90_description/meshes/12GAN20__1__Mirror__1.stl" scale="0.001 0.001 0.001"/>
    </geometry>
    <material name="silver"/>
  </visual>
  <collision>
    <origin rpy="0 0 0" xyz="0.096451 -0.099054 -0.001"/>
    <geometry>
      <mesh filename="package://ppp90_description/meshes/12GAN20__1__Mirror__1.stl" scale="0.001 0.001 0.001"/>
    </geometry>
  </collision>
</link>

<!-- -->
<link name="Forward_wheel">
   <inertial>
    <origin rpy="0 0 0" xyz="-0.0052579363728012885 -0.10377441452254206 -0.015"/>
    <mass value="0.0061871055650105375"/>
    <inertia ixx="0.0" ixy="-0.0" ixz="0.0" iyy="0.0" iyz="-0.0" izz="1e-06"/>
  </inertial>
  <visual>
    <origin rpy="0 0 0" xyz="-0.0052579363728012885 -0.10377441452254206 -0.015"/>
    <geometry>
      <mesh filename="package://ppp90_description/meshes/Forward_wheel.stl" scale="0.001 0.001 0.001"/>
    </geometry>
    <material name="red"/>
  </visual>
  <collision>
    <origin rpy="0 0 0" xyz="-0.0052579363728012885 -0.10377441452254206 -0.015"/>
    <geometry>
      <mesh filename="package://ppp90_description/meshes/Forward_wheel.stl" scale="0.001 0.001 0.001"/>
    </geometry>
  </collision>
</link>


<link name="fw_wheel_1">
  <inertial>
    <origin rpy="0 0 0" xyz="0.037938230253998714 0.09960326638090941 -0.04141690237825763"/>
    <mass value="0.0030764824061019756"/>
    <inertia ixx="0.0" ixy="-0.0" ixz="0.0" iyy="0.0" iyz="0.0" izz="0.0"/>
  </inertial>
  <visual>
    <origin rpy="0 0 0" xyz="0.024889 -0.006 -0.03591"/>
    <geometry>
      <mesh filename="package://ppp90_description/meshes/fw_wheel_1.stl" scale="0.001 0.001 0.001"/>
    </geometry>
    <material name="yellow"/>
  </visual>
  <collision>
    <origin rpy="0 0 0" xyz="0.024889 -0.006 -0.03591"/>
    <geometry>
      <mesh filename="package://ppp90_description/meshes/fw_wheel_1.stl" scale="0.001 0.001 0.001"/>
    </geometry>
  </collision>
</link>

<link name="holder1_1">
  <inertial>
    <origin rpy="0 0 0" xyz="0.05994756275850843 0.0810927236228087 0.003681014204852218"/>
    <mass value="0.006489971019909515"/>
    <inertia ixx="1e-06" ixy="0.0" ixz="0.0" iyy="0.0" iyz="0.0" izz="1e-06"/>
  </inertial>
  <visual>
    <origin rpy="0 0 0" xyz="0.053573 -0.022977 -0.0025"/>
    <geometry>
      <mesh filename="package://ppp90_description/meshes/holder1_1.stl" scale="0.001 0.001 0.001"/>
    </geometry>
    <material name="green"/>
  </visual>
  <collision>
    <origin rpy="0 0 0" xyz="0.053573 -0.022977 -0.0025"/>
    <geometry>
      <mesh filename="package://ppp90_description/meshes/holder1_1.stl" scale="0.001 0.001 0.001"/>
    </geometry>
  </collision>
</link>

<link name="holder2_1">
  <inertial>
    <origin rpy="0 0 0" xyz="-0.012242063627652948 0.08877441452254206 0.011845529293967897"/>
    <mass value="0.002767366136694294"/>
    <inertia ixx="0.0" ixy="0.0" ixz="-0.0" iyy="0.0" iyz="-0.0" izz="0.0"/>
  </inertial>
  <visual>
    <origin rpy="0 0 0" xyz="-0.0175 -0.015 0.0"/>
    <geometry>
      <mesh filename="package://ppp90_description/meshes/holder2_1.stl" scale="0.001 0.001 0.001"/>
    </geometry>
    <material name="d_blue"/>
  </visual>
  <collision>
    <origin rpy="0 0 0" xyz="-0.0175 -0.015 0.0"/>
    <geometry>
      <mesh filename="package://ppp90_description/meshes/holder2_1.stl" scale="0.001 0.001 0.001"/>
    </geometry>
  </collision>
</link>

<link name="fww_a_1">
  <inertial>
    <origin rpy="0 0 0" xyz="0.0379390477443535 0.11460348542678987 -0.04141447070571836"/>
    <mass value="0.0043107049436968805"/>
    <inertia ixx="0.0" ixy="0.0" ixz="0.0" iyy="0.0" iyz="0.0" izz="0.0"/>
  </inertial>
  <visual>
    <origin rpy="0 0 0" xyz="0.024889 0.009 -0.03591"/>
    <geometry>
      <mesh filename="package://ppp90_description/meshes/fww_a_1.stl" scale="0.001 0.001 0.001"/>
    </geometry>
    <material name="silver"/>
  </visual>
  <collision>
    <origin rpy="0 0 0" xyz="0.024889 0.009 -0.03591"/>
    <geometry>
      <mesh filename="package://ppp90_description/meshes/fww_a_1.stl" scale="0.001 0.001 0.001"/>
    </geometry>
  </collision>
</link>

<joint name="Rigid19" type="fixed">
  <origin rpy="0 0 1.5708" xyz="-0.120925 -0.014338 0.022"/>
  <parent link="base_link"/>
  <child link="Forward_wheel"/>
</joint>

<joint name="Rev11" type="continuous">
  <origin rpy="0 0 0" xyz="0.0 0.015 0.0"/>
  <parent link="fww_a_1"/>
  <child link="fw_wheel_1"/>
  <axis xyz="-0.258819 0.965926 0.0"/>
</joint>

<joint name="Rev21" type="continuous">
  <origin rpy="0 0 0" xyz="-0.071073 0.007977 0.0025"/>
  <parent link="holder2_1"/>
  <child link="holder1_1"/>
  <axis xyz="-0.0 0.0 -1.0"/>
</joint>

<joint name="Rev31" type="continuous">
  <origin rpy="0 0 0" xyz="0.0175 -0.09 -0.015"/>
  <parent link="Forward_wheel"/>
  <child link="holder2_1"/>
  <axis xyz="0.0 -0.0 1.0"/>
</joint>

<joint name="Rev41" type="continuous">
  <origin rpy="0 0 0" xyz="0.028684 -0.031977 0.03341"/>
  <parent link="holder1_1"/>
  <child link="fww_a_1"/>
  <axis xyz="0.258819 -0.965926 -0.0"/>
</joint>









<!-- -->



<link name="forward_top_1_1">
  <inertial>
    <origin rpy="0 0 0" xyz="0.09472417565339834 0.0650218967379826 0.0004895173930853647"/>
    <mass value="0.48710215659029577"/>
    <inertia ixx="0.000784" ixy="-0.000235" ixz="1e-06" iyy="0.00099" iyz="1e-06" izz="0.001773"/>
  </inertial>
  <visual>
    <origin rpy="0 0 0" xyz="0.163494 0.014338 -0.11"/>
    <geometry>
      <mesh filename="package://ppp90_description/meshes/forward_top_1_1.stl" scale="0.001 0.001 0.001"/>
    </geometry>
    <material name="silver"/>
  </visual>
  <collision>
    <origin rpy="0 0 0" xyz="0.163494 0.014338 -0.11"/>
    <geometry>
      <mesh filename="package://ppp90_description/meshes/forward_top_1_1.stl" scale="0.001 0.001 0.001"/>
    </geometry>
  </collision>
</link>

<link name="forward_top_1_Mirror__1">
  <inertial>
    <origin rpy="0 0 0" xyz="-0.07359144458337072 0.07845770313065512 0.0004895171912022017"/>
    <mass value="0.48710223650351714"/>
    <inertia ixx="0.000784" ixy="0.000234" ixz="1e-06" iyy="0.00099" iyz="-1e-06" izz="0.001773"/>
  </inertial>
  <visual>
    <origin rpy="0 0 0" xyz="-0.004866 0.157868 -0.11"/>
    <geometry>
      <mesh filename="package://ppp90_description/meshes/forward_top_1_Mirror__1.stl" scale="0.001 0.001 0.001"/>
    </geometry>
    <material name="silver"/>
  </visual>
  <collision>
    <origin rpy="0 0 0" xyz="-0.004866 0.157868 -0.11"/>
    <geometry>
      <mesh filename="package://ppp90_description/meshes/forward_top_1_Mirror__1.stl" scale="0.001 0.001 0.001"/>
    </geometry>
  </collision>
</link>

<link name="back_top_1">
  <inertial>
    <origin rpy="0 0 0" xyz="0.06983870948069765 0.07365312062764642 -0.001088719949768488"/>
    <mass value="0.23560428740017997"/>
    <inertia ixx="0.000537" ixy="-0.000345" ixz="1.3e-05" iyy="0.00038" iyz="1.8e-05" izz="0.000907"/>
  </inertial>
  <visual>
    <origin rpy="0 0 0" xyz="-0.004866 0.157868 -0.11"/>
    <geometry>
      <mesh filename="package://ppp90_description/meshes/back_top_1.stl" scale="0.001 0.001 0.001"/>
    </geometry>
    <material name="silver"/>
  </visual>
  <collision>
    <origin rpy="0 0 0" xyz="-0.004866 0.157868 -0.11"/>
    <geometry>
      <mesh filename="package://ppp90_description/meshes/back_top_1.stl" scale="0.001 0.001 0.001"/>
    </geometry>
  </collision>
</link>

<link name="back_top2_1">
  <inertial>
    <origin rpy="0 0 0" xyz="0.05870883159733394 -0.05499680190680151 0.0004968868769273244"/>
    <mass value="0.18961170684744505"/>
    <inertia ixx="0.000183" ixy="0.000153" ixz="-1e-06" iyy="0.000249" iyz="1e-06" izz="0.000432"/>
  </inertial>
  <visual>
    <origin rpy="0 0 0" xyz="-0.004866 -0.129192 -0.11"/>
    <geometry>
      <mesh filename="package://ppp90_description/meshes/back_top2_1.stl" scale="0.001 0.001 0.001"/>
    </geometry>
    <material name="silver"/>
  </visual>
  <collision>
    <origin rpy="0 0 0" xyz="-0.004866 -0.129192 -0.11"/>
    <geometry>
      <mesh filename="package://ppp90_description/meshes/back_top2_1.stl" scale="0.001 0.001 0.001"/>
    </geometry>
  </collision>
</link>

<link name="Lidar_1">
  <inertial>
    <origin rpy="0 0 0" xyz="1.561464430532844e-07 1.323739005389124e-08 0.03500000000000007"/>
    <mass value="2.114723824855799"/>
    <inertia ixx="0.001511" ixy="-0.0" ixz="0.0" iyy="0.001511" iyz="-0.0" izz="0.001295"/>
  </inertial>
  <visual>
    <origin rpy="0 0 0" xyz="0.110814 0.014417 -0.112"/>
    <geometry>
      <mesh filename="package://ppp90_description/meshes/Lidar_1.stl" scale="0.001 0.001 0.001"/>
    </geometry>
    <material name="silver"/>
  </visual>
  <collision>
    <origin rpy="0 0 0" xyz="0.110814 0.014417 -0.112"/>
    <geometry>
      <mesh filename="package://ppp90_description/meshes/Lidar_1.stl" scale="0.001 0.001 0.001"/>
    </geometry>
  </collision>
</link>

<link name="base_imu_link">
  <inertial>
    <origin rpy="0 0 0" xyz="-4.3047029232856637e-07 -9.471075246465788e-08 0.007500000000000041"/>
    <mass value="0.011774999999999999"/>
    <inertia ixx="1e-06" ixy="0.0" ixz="0.0" iyy="0.0" iyz="-0.0" izz="0.0"/>
  </inertial>
  <visual>
    <origin rpy="0 0 0" xyz="0.159074 0.014338 -0.033"/>
    <geometry>
      <mesh filename="package://ppp90_description/meshes/IMU_1.stl" scale="0.001 0.001 0.001"/>
    </geometry>
    <material name="silver"/>
  </visual>
  <collision>
    <origin rpy="0 0 0" xyz="0.159074 0.014338 -0.033"/>
    <geometry>
      <mesh filename="package://ppp90_description/meshes/IMU_1.stl" scale="0.001 0.001 0.001"/>
    </geometry>
  </collision>
</link>

<joint name="Rev1" type="continuous">
  <origin rpy="0 0 0" xyz="0.0 0.04585 0.021125"/>
  <parent link="nema17_1"/>
  <child link="wheel_1"/>
  <axis xyz="-0.0 1.0 -0.0"/>
</joint>

<joint name="Rev4" type="continuous">
  <origin rpy="0 0 0" xyz="3.7e-05 -0.02285 0.021125"/>
  <parent link="nema17_Mirror__1"/>
  <child link="wheel_Mirror__1"/>
  <axis xyz="0.001615 -0.999999 0.0"/>
</joint>

<joint name="Rigid5" type="fixed">
  <origin rpy="0 0 1.50" xyz="-0.027494 0.13623 0.08983"/>
  <parent link="base_link"/>
  <child link="sonyc_1"/>
</joint>

<joint name="Rigid6" type="fixed">
  <origin rpy="0 0 -1.65" xyz="-0.001494 -0.164906 0.08983"/>
  <parent link="base_link"/>
  <child link="sonyc_Mirror__1"/>
</joint>

<joint name="Rigid7" type="fixed">
  <origin rpy="0 0 -3.14159" xyz="-0.169414 -0.001361 0.06983"/>
  <parent link="base_link"/>
  <child link="sonyc__1__1"/>
</joint>

<joint name="Rigid8" type="fixed">
  <origin rpy="0 0 0" xyz="-0.014494 0.084071 0.003"/>
  <parent link="base_link"/>
  <child link="nema17_1"/>
</joint>

<joint name="Rigid9" type="fixed">
  <origin rpy="0 0 0" xyz="-0.014528 -0.113338 0.003"/>
  <parent link="base_link"/>
  <child link="nema17_Mirror__1"/>
</joint>

<joint name="Rigid13" type="fixed">
  <origin rpy="0 0 0" xyz="-0.096453 -0.12774 0.001"/>
  <parent link="base_link"/>
  <child link="12GAN20__1__1"/>
</joint>

<joint name="Rev14" type="continuous">
  <origin rpy="0 0 0" xyz="-2e-06 -1e-05 -0.002"/>
  <parent link="12GAN20__1__1"/>
  <child link="brush_1"/>
  <axis xyz="-0.0 0.0 -1.0"/>
</joint>

<joint name="Rev15" type="continuous">
  <origin rpy="0 0 0" xyz="0.0 0.0 -0.002"/>
  <parent link="12GAN20__1__Mirror__1"/>
  <child link="brush_Mirror__1"/>
  <axis xyz="0.0 -0.0 -1.0"/>
</joint>

<joint name="Rigid16" type="fixed">
  <origin rpy="0 0 0" xyz="-0.096451 0.099054 0.001"/>
  <parent link="base_link"/>
  <child link="12GAN20__1__Mirror__1"/>
</joint>


<joint name="Rigid21" type="fixed">
  <origin rpy="0 0 0" xyz="-0.163494 -0.014338 0.11"/>
  <parent link="base_link"/>
  <child link="forward_top_1_1"/>
</joint>

<joint name="Rigid22" type="fixed">
  <origin rpy="0 0 0" xyz="0.004866 -0.157868 0.11"/>
  <parent link="base_link"/>
  <child link="forward_top_1_Mirror__1"/>
</joint>

<joint name="Rigid23" type="fixed">
  <origin rpy="0 0 0" xyz="0.004866 -0.157868 0.11"/>
  <parent link="base_link"/>
  <child link="back_top_1"/>
</joint>

<joint name="Rigid24" type="fixed">
  <origin rpy="0 0 0" xyz="0.004866 0.129192 0.11"/>
  <parent link="base_link"/>
  <child link="back_top2_1"/>
</joint>

<joint name="Rigid25" type="fixed">
  <origin rpy="0 0 0" xyz="-0.11568 0.143451 0.002"/>
  <parent link="forward_top_1_Mirror__1"/>
  <child link="Lidar_1"/>
</joint>

<joint name="Rigid26" type="fixed">
  <origin rpy="0 0 0" xyz="-0.159074 -0.014338 0.033"/>
  <parent link="base_link"/>
  <child link="base_imu_link"/>
</joint>

</robot>
