<?xml version="1.0" ?>
<robot name="ppp" xmlns:xacro="http://www.ros.org/wiki/xacro">

<xacro:include filename="$(find ppp_description)/urdf/materials.xacro" />
<xacro:include filename="$(find ppp_description)/urdf/ppp.trans" />
<xacro:include filename="$(find ppp_description)/urdf/ppp.gazebo" />
<link name="base_link">
  <inertial>
    <origin rpy="0 0 0" xyz="0.00035991844972606176 -0.002214267330423183 0.0335388171748763"/>
    <mass value="4.841614189321788"/>
    <inertia ixx="0.041089" ixy="2e-06" ixz="-6.2e-05" iyy="0.036707" iyz="0.001294" izz="0.067162"/>
  </inertial>
  <visual>
    <origin rpy="0 0 0" xyz="0 0 0"/>
    <geometry>
      <mesh filename="package://ppp_description/meshes/base_link.stl" scale="0.001 0.001 0.001"/>
    </geometry>
    <material name="silver"/>
  </visual>
  <collision>
    <origin rpy="0 0 0" xyz="0 0 0"/>
    <geometry>
      <mesh filename="package://ppp_description/meshes/base_link.stl" scale="0.001 0.001 0.001"/>
    </geometry>
  </collision>
</link>

<link name="wheel_1">
  <inertial>
    <origin rpy="0 0 0" xyz="-0.011999716937678151 4.806923526791906e-05 -0.0002947640001165798"/>
    <mass value="0.7647072407364309"/>
    <inertia ixx="0.000502" ixy="0.0" ixz="0.0" iyy="0.000285" iyz="-0.0" izz="0.000285"/>
  </inertial>
  <visual>
    <origin rpy="0 0 0" xyz="-0.144259 -0.0 -0.024125"/>
    <geometry>
      <mesh filename="package://ppp_description/meshes/wheel_1.stl" scale="0.001 0.001 0.001"/>
    </geometry>
    <material name="silver"/>
  </visual>
  <collision>
    <origin rpy="0 0 0" xyz="-0.144259 -0.0 -0.024125"/>
    <geometry>
      <mesh filename="package://ppp_description/meshes/wheel_1.stl" scale="0.001 0.001 0.001"/>
    </geometry>
  </collision>
</link>

<link name="wheel_Mirror__1">
  <inertial>
    <origin rpy="0 0 0" xyz="-0.011999769370161381 -0.00015102030089534307 0.00026807201904404526"/>
    <mass value="0.7647072407364308"/>
    <inertia ixx="0.000502" ixy="0.0" ixz="0.0" iyy="0.000285" iyz="-0.0" izz="0.000285"/>
  </inertial>
  <visual>
    <origin rpy="0 0 0" xyz="0.12185 3e-06 -0.024125"/>
    <geometry>
      <mesh filename="package://ppp_description/meshes/wheel_Mirror__1.stl" scale="0.001 0.001 0.001"/>
    </geometry>
    <material name="silver"/>
  </visual>
  <collision>
    <origin rpy="0 0 0" xyz="0.12185 3e-06 -0.024125"/>
    <geometry>
      <mesh filename="package://ppp_description/meshes/wheel_Mirror__1.stl" scale="0.001 0.001 0.001"/>
    </geometry>
  </collision>
</link>

<link name="sonyc_1">
  <inertial>
    <origin rpy="0 0 0" xyz="-0.010235420309224613 -0.012999995558067955 5.063181308696818e-05"/>
    <mass value="0.0252883585593009"/>
    <inertia ixx="5e-06" ixy="-0.0" ixz="-0.0" iyy="1e-06" iyz="-0.0" izz="5e-06"/>
  </inertial>
  <visual>
    <origin rpy="0 0 0" xyz="-0.150568 -0.013 -0.08983"/>
    <geometry>
      <mesh filename="package://ppp_description/meshes/sonyc_1.stl" scale="0.001 0.001 0.001"/>
    </geometry>
    <material name="silver"/>
  </visual>
  <collision>
    <origin rpy="0 0 0" xyz="-0.150568 -0.013 -0.08983"/>
    <geometry>
      <mesh filename="package://ppp_description/meshes/sonyc_1.stl" scale="0.001 0.001 0.001"/>
    </geometry>
  </collision>
</link>

<link name="sonyc_Mirror__1">
  <inertial>
    <origin rpy="0 0 0" xyz="0.010235420309224252 0.01300000444193195 5.063181308696818e-05"/>
    <mass value="0.025288358559300887"/>
    <inertia ixx="5e-06" ixy="0.0" ixz="0.0" iyy="1e-06" iyz="-0.0" izz="5e-06"/>
  </inertial>
  <visual>
    <origin rpy="0 0 0" xyz="0.150568 0.013 -0.08983"/>
    <geometry>
      <mesh filename="package://ppp_description/meshes/sonyc_Mirror__1.stl" scale="0.001 0.001 0.001"/>
    </geometry>
    <material name="silver"/>
  </visual>
  <collision>
    <origin rpy="0 0 0" xyz="0.150568 0.013 -0.08983"/>
    <geometry>
      <mesh filename="package://ppp_description/meshes/sonyc_Mirror__1.stl" scale="0.001 0.001 0.001"/>
    </geometry>
  </collision>
</link>

<link name="sonyc__1__1">
  <inertial>
    <origin rpy="0 0 0" xyz="-0.01300032439616085 -0.010236078078188549 5.06318130869543e-05"/>
    <mass value="0.0252883585593009"/>
    <inertia ixx="1e-06" ixy="0.0" ixz="0.0" iyy="5e-06" iyz="-0.0" izz="5e-06"/>
  </inertial>
  <visual>
    <origin rpy="0 0 0" xyz="-0.012977 -0.154921 -0.06983"/>
    <geometry>
      <mesh filename="package://ppp_description/meshes/sonyc__1__1.stl" scale="0.001 0.001 0.001"/>
    </geometry>
    <material name="silver"/>
  </visual>
  <collision>
    <origin rpy="0 0 0" xyz="-0.012977 -0.154921 -0.06983"/>
    <geometry>
      <mesh filename="package://ppp_description/meshes/sonyc__1__1.stl" scale="0.001 0.001 0.001"/>
    </geometry>
  </collision>
</link>

<link name="nema17_1">
  <inertial>
    <origin rpy="0 0 0" xyz="-0.003342487143977363 1.0409113986613717e-06 0.02118013525930302"/>
    <mass value="0.1838412954712099"/>
    <inertia ixx="5.3e-05" ixy="0.0" ixz="0.0" iyy="5.2e-05" iyz="0.0" izz="5.2e-05"/>
  </inertial>
  <visual>
    <origin rpy="0 0 0" xyz="-0.098409 -0.0 -0.003"/>
    <geometry>
      <mesh filename="package://ppp_description/meshes/nema17_1.stl" scale="0.001 0.001 0.001"/>
    </geometry>
    <material name="silver"/>
  </visual>
  <collision>
    <origin rpy="0 0 0" xyz="-0.098409 -0.0 -0.003"/>
    <geometry>
      <mesh filename="package://ppp_description/meshes/nema17_1.stl" scale="0.001 0.001 0.001"/>
    </geometry>
  </collision>
</link>

<link name="nema17_Mirror__1">
  <inertial>
    <origin rpy="0 0 0" xyz="0.0033427367952116732 6.3450027137950304e-06 0.021180135259303026"/>
    <mass value="0.1838412954712099"/>
    <inertia ixx="5.3e-05" ixy="0.0" ixz="-0.0" iyy="5.2e-05" iyz="0.0" izz="5.2e-05"/>
  </inertial>
  <visual>
    <origin rpy="0 0 0" xyz="0.099 -3.4e-05 -0.003"/>
    <geometry>
      <mesh filename="package://ppp_description/meshes/nema17_Mirror__1.stl" scale="0.001 0.001 0.001"/>
    </geometry>
    <material name="silver"/>
  </visual>
  <collision>
    <origin rpy="0 0 0" xyz="0.099 -3.4e-05 -0.003"/>
    <geometry>
      <mesh filename="package://ppp_description/meshes/nema17_Mirror__1.stl" scale="0.001 0.001 0.001"/>
    </geometry>
  </collision>
</link>

<link name="12GAN20__1__1">
  <inertial>
    <origin rpy="0 0 0" xyz="-3.292631452073147e-06 -6.626992531399978e-07 0.01185787133707267"/>
    <mass value="0.023492103087793172"/>
    <inertia ixx="2e-06" ixy="0.0" ixz="-0.0" iyy="1e-06" iyz="0.0" izz="0.0"/>
  </inertial>
  <visual>
    <origin rpy="0 0 0" xyz="0.113402 -0.08196 -0.001"/>
    <geometry>
      <mesh filename="package://ppp_description/meshes/12GAN20__1__1.stl" scale="0.001 0.001 0.001"/>
    </geometry>
    <material name="silver"/>
  </visual>
  <collision>
    <origin rpy="0 0 0" xyz="0.113402 -0.08196 -0.001"/>
    <geometry>
      <mesh filename="package://ppp_description/meshes/12GAN20__1__1.stl" scale="0.001 0.001 0.001"/>
    </geometry>
  </collision>
</link>

<link name="brush_1">
  <inertial>
    <origin rpy="0 0 0" xyz="-7.733309837359981e-07 3.2946715564086126e-08 -0.002220419930831826"/>
    <mass value="0.014937067448072668"/>
    <inertia ixx="1e-06" ixy="-0.0" ixz="0.0" iyy="1e-06" iyz="-0.0" izz="2e-06"/>
  </inertial>
  <visual>
    <origin rpy="0 0 0" xyz="0.113412 -0.081962 0.001"/>
    <geometry>
      <mesh filename="package://ppp_description/meshes/brush_1.stl" scale="0.001 0.001 0.001"/>
    </geometry>
    <material name="silver"/>
  </visual>
  <collision>
    <origin rpy="0 0 0" xyz="0.113412 -0.081962 0.001"/>
    <geometry>
      <mesh filename="package://ppp_description/meshes/brush_1.stl" scale="0.001 0.001 0.001"/>
    </geometry>
  </collision>
</link>

<link name="brush_Mirror__1">
  <inertial>
    <origin rpy="0 0 0" xyz="-5.614420228589045e-07 -1.2298749614975124e-06 -0.0022204199308317844"/>
    <mass value="0.014937067448072664"/>
    <inertia ixx="1e-06" ixy="-0.0" ixz="0.0" iyy="1e-06" iyz="0.0" izz="2e-06"/>
  </inertial>
  <visual>
    <origin rpy="0 0 0" xyz="-0.113393 -0.081958 0.001"/>
    <geometry>
      <mesh filename="package://ppp_description/meshes/brush_Mirror__1.stl" scale="0.001 0.001 0.001"/>
    </geometry>
    <material name="silver"/>
  </visual>
  <collision>
    <origin rpy="0 0 0" xyz="-0.113393 -0.081958 0.001"/>
    <geometry>
      <mesh filename="package://ppp_description/meshes/brush_Mirror__1.stl" scale="0.001 0.001 0.001"/>
    </geometry>
  </collision>
</link>

<link name="12GAN20__1__Mirror__1">
  <inertial>
    <origin rpy="0 0 0" xyz="-7.3554193489588915e-06 -2.6912147267910136e-06 0.011857871337072678"/>
    <mass value="0.02349210308779317"/>
    <inertia ixx="2e-06" ixy="-0.0" ixz="0.0" iyy="1e-06" iyz="0.0" izz="0.0"/>
  </inertial>
  <visual>
    <origin rpy="0 0 0" xyz="-0.113393 -0.081958 -0.001"/>
    <geometry>
      <mesh filename="package://ppp_description/meshes/12GAN20__1__Mirror__1.stl" scale="0.001 0.001 0.001"/>
    </geometry>
    <material name="silver"/>
  </visual>
  <collision>
    <origin rpy="0 0 0" xyz="-0.113393 -0.081958 -0.001"/>
    <geometry>
      <mesh filename="package://ppp_description/meshes/12GAN20__1__Mirror__1.stl" scale="0.001 0.001 0.001"/>
    </geometry>
  </collision>
</link>

<link name="Forward_wheel_base_1">
  <inertial>
    <origin rpy="0 0 0" xyz="3.595124198341181e-14 -1.1035397282088688e-07 -0.0014374507094137567"/>
    <mass value="0.0061871055650105375"/>
    <inertia ixx="0.0" ixy="-0.0" ixz="0.0" iyy="0.0" iyz="-0.0" izz="1e-06"/>
  </inertial>
  <visual>
    <origin rpy="0 0 0" xyz="-0.0 -0.106431 -0.022"/>
    <geometry>
      <mesh filename="package://ppp_description/meshes/Forward_wheel_base_1.stl" scale="0.001 0.001 0.001"/>
    </geometry>
    <material name="silver"/>
  </visual>
  <collision>
    <origin rpy="0 0 0" xyz="-0.0 -0.106431 -0.022"/>
    <geometry>
      <mesh filename="package://ppp_description/meshes/Forward_wheel_base_1.stl" scale="0.001 0.001 0.001"/>
    </geometry>
  </collision>
</link>

<joint name="wheel_to_nema17" type="continuous">
  <origin rpy="0 0 0" xyz="0.04585 0.0 0.021125"/>
  <parent link="nema17_1"/>
  <child link="wheel_1"/>
  <axis xyz="1.0 0.0 -0.0"/>
</joint>

<joint name="wheel_to_nema17_2" type="continuous">
  <origin rpy="0 0 0" xyz="-0.02285 -3.7e-05 0.021125"/>
  <parent link="nema17_Mirror__1"/>
  <child link="wheel_Mirror__1"/>
  <axis xyz="-0.999999 -0.001615 0.0"/>
</joint>

<joint name="ultra_sonyc_to_main" type="fixed">
  <origin rpy="0 0 0" xyz="0.150568 0.013 0.08983"/>
  <parent link="base_link"/>
  <child link="sonyc_1"/>
</joint>

<joint name="ultra_sonyc_to_main_2" type="fixed">
  <origin rpy="0 0 0" xyz="-0.150568 -0.013 0.08983"/>
  <parent link="base_link"/>
  <child link="sonyc_Mirror__1"/>
</joint>

<joint name="ultra_sonyc_to_main_3" type="fixed">
  <origin rpy="0 0 0" xyz="0.012977 0.154921 0.06983"/>
  <parent link="base_link"/>
  <child link="sonyc__1__1"/>
</joint>

<joint name="name_to_main" type="fixed">
  <origin rpy="0 0 0" xyz="0.098409 0.0 0.003"/>
  <parent link="base_link"/>
  <child link="nema17_1"/>
</joint>

<joint name="name_to_main_2" type="fixed">
  <origin rpy="0 0 0" xyz="-0.099 3.4e-05 0.003"/>
  <parent link="base_link"/>
  <child link="nema17_Mirror__1"/>
</joint>

<joint name="motor_brash_to_main" type="fixed">
  <origin rpy="0 0 0" xyz="-0.113402 0.08196 0.001"/>
  <parent link="base_link"/>
  <child link="12GAN20__1__1"/>
</joint>

<joint name="motor_to_brash" type="continuous">
  <origin rpy="0 0 0" xyz="-1e-05 2e-06 -0.002"/>
  <parent link="12GAN20__1__1"/>
  <child link="brush_1"/>
  <axis xyz="0.0 -0.0 -1.0"/>
</joint>

<joint name="motor_to_brash (1)" type="continuous">
  <origin rpy="0 0 0" xyz="0.0 0.0 -0.002"/>
  <parent link="12GAN20__1__Mirror__1"/>
  <child link="brush_Mirror__1"/>
  <axis xyz="-0.0 -0.0 -1.0"/>
</joint>

<joint name="motor_brash_to_main_2" type="fixed">
  <origin rpy="0 0 0" xyz="0.113393 0.081958 0.001"/>
  <parent link="base_link"/>
  <child link="12GAN20__1__Mirror__1"/>
</joint>

<joint name="forward_wheel_to_main" type="fixed">
  <origin rpy="0 0 0" xyz="0.0 0.106431 0.022"/>
  <parent link="base_link"/>
  <child link="Forward_wheel_base_1"/>
</joint>

</robot>
