<?xml version="1.0" ?>
<robot name="ppp" xmlns:xacro="http://www.ros.org/wiki/xacro">

<xacro:include filename="$(find ppp_description)/urdf/materials.xacro" />
<xacro:include filename="$(find ppp_description)/urdf/ppp.trans" />
<xacro:include filename="$(find ppp_description)/urdf/ppp.gazebo" />
<link name="base_link">
  <inertial>
    <origin rpy="0 0 0" xyz="1.5201671826907086e-05 -0.0012107786655712151 0.03300924453524418"/>
    <mass value="4.737374361291242"/>
    <inertia ixx="0.040333" ixy="-5e-06" ixz="-1e-05" iyy="0.036454" iyz="0.001185" izz="0.066412"/>
  </inertial>
  <visual>
    <origin rpy="0 0 0" xyz="0 0 0"/>
    <geometry>
      <mesh filename="package://ppp_description/meshes/base_link.stl" scale="0.001 0.001 0.001"/>
    </geometry>
    <material name="silver"/>
  </visual>
  <collision>
    <origin rpy="0 0 0" xyz="0 0 0"/>
    <geometry>
      <mesh filename="package://ppp_description/meshes/base_link.stl" scale="0.001 0.001 0.001"/>
    </geometry>
  </collision>
</link>

<link name="wheel_1">
  <inertial>
    <origin rpy="0 0 0" xyz="-0.01199971693767804 6.38590668516137e-05 -0.0002917507270338848"/>
    <mass value="0.7647072407364309"/>
    <inertia ixx="0.000502" ixy="0.0" ixz="0.0" iyy="0.000285" iyz="-0.0" izz="0.000285"/>
  </inertial>
  <visual>
    <origin rpy="0 0 0" xyz="-0.144259 -0.0 -0.024125"/>
    <geometry>
      <mesh filename="package://ppp_description/meshes/wheel_1.stl" scale="0.001 0.001 0.001"/>
    </geometry>
    <material name="silver"/>
  </visual>
  <collision>
    <origin rpy="0 0 0" xyz="-0.144259 -0.0 -0.024125"/>
    <geometry>
      <mesh filename="package://ppp_description/meshes/wheel_1.stl" scale="0.001 0.001 0.001"/>
    </geometry>
  </collision>
</link>

<link name="wheel_Mirror__1">
  <inertial>
    <origin rpy="0 0 0" xyz="-0.011999769370161381 -0.00015102030089534307 0.00026807201904404526"/>
    <mass value="0.7647072407364308"/>
    <inertia ixx="0.000502" ixy="0.0" ixz="0.0" iyy="0.000285" iyz="-0.0" izz="0.000285"/>
  </inertial>
  <visual>
    <origin rpy="0 0 0" xyz="0.12185 3e-06 -0.024125"/>
    <geometry>
      <mesh filename="package://ppp_description/meshes/wheel_Mirror__1.stl" scale="0.001 0.001 0.001"/>
    </geometry>
    <material name="silver"/>
  </visual>
  <collision>
    <origin rpy="0 0 0" xyz="0.12185 3e-06 -0.024125"/>
    <geometry>
      <mesh filename="package://ppp_description/meshes/wheel_Mirror__1.stl" scale="0.001 0.001 0.001"/>
    </geometry>
  </collision>
</link>

<link name="sonyc_1">
  <inertial>
    <origin rpy="0 0 0" xyz="-0.010235420309224613 -0.012999995558067955 5.063181308696818e-05"/>
    <mass value="0.0252883585593009"/>
    <inertia ixx="5e-06" ixy="-0.0" ixz="-0.0" iyy="1e-06" iyz="-0.0" izz="5e-06"/>
  </inertial>
  <visual>
    <origin rpy="0 0 0" xyz="-0.150568 -0.013 -0.08983"/>
    <geometry>
        <box size="0.001 0.0005 0.00035"/>
      <!-- <mesh filename="package://ppp_description/meshes/sonyc_1.stl" scale="0.001 0.001 0.001"/> -->
    </geometry>
    <material name="silver"/>
  </visual>
  <!-- <collision>
    <origin rpy="0 0 0" xyz="-0.150568 -0.013 -0.08983"/>
    <geometry>
      <mesh filename="package://ppp_description/meshes/sonyc_1.stl" scale="0.001 0.001 0.001"/>
    </geometry>
  </collision> -->
</link>

<link name="sonyc_Mirror__1">
  <inertial>
    <origin rpy="0 0 0" xyz="0.010235420309224252 0.01300000444193195 5.063181308696818e-05"/>
    <mass value="0.025288358559300887"/>
    <inertia ixx="5e-06" ixy="0.0" ixz="0.0" iyy="1e-06" iyz="-0.0" izz="5e-06"/>
  </inertial>
  <visual>
    <origin rpy="0 0 0" xyz="0.150568 0.013 -0.08983"/>
    <geometry>
        <box size="0.001 0.0005 0.00035"/>
      <!-- <mesh filename="package://ppp_description/meshes/sonyc_Mirror__1.stl" scale="0.001 0.001 0.001"/>  -->
    </geometry>
    <material name="silver"/>
  </visual>
  <!-- <collision>
    <origin rpy="0 0 0" xyz="0.150568 0.013 -0.08983"/>
    <geometry>
      <mesh filename="package://ppp_description/meshes/sonyc_Mirror__1.stl" scale="0.001 0.001 0.001"/>
    </geometry>
  </collision> -->
</link>

<link name="sonyc__1__1">
  <inertial>
    <origin rpy="0 0 0" xyz="-0.01300032439616085 -0.010236078078188549 5.06318130869543e-05"/>
    <mass value="0.0252883585593009"/>
    <inertia ixx="1e-06" ixy="0.0" ixz="0.0" iyy="5e-06" iyz="-0.0" izz="5e-06"/>
  </inertial>
  <visual>
    <origin rpy="0 0 0" xyz="-0.012977 -0.154921 -0.06983"/>
    <geometry>
        <box size="0.001 0.0005 0.00035"/>
      <!-- <mesh filename="package://ppp_description/meshes/sonyc__1__1.stl" scale="0.001 0.001 0.001"/> -->
    </geometry>
    <material name="silver"/>
  </visual>
  <!-- <collision>
    <origin rpy="0 0 0" xyz="-0.012977 -0.154921 -0.06983"/>
    <geometry>
      <mesh filename="package://ppp_description/meshes/sonyc__1__1.stl" scale="0.001 0.001 0.001"/>
    </geometry>
  </collision> -->
</link>

<link name="nema17_1">
  <inertial>
    <origin rpy="0 0 0" xyz="-0.003342487143977363 1.0409113986613717e-06 0.02118013525930302"/>
    <mass value="0.1838412954712099"/>
    <inertia ixx="5.3e-05" ixy="0.0" ixz="0.0" iyy="5.2e-05" iyz="0.0" izz="5.2e-05"/>
  </inertial>
  <visual>
    <origin rpy="0 0 0" xyz="-0.098409 -0.0 -0.003"/>
    <geometry>
      <mesh filename="package://ppp_description/meshes/nema17_1.stl" scale="0.001 0.001 0.001"/>
    </geometry>
    <material name="silver"/>
  </visual>
  <collision>
    <origin rpy="0 0 0" xyz="-0.098409 -0.0 -0.003"/>
    <geometry>
      <mesh filename="package://ppp_description/meshes/nema17_1.stl" scale="0.001 0.001 0.001"/>
    </geometry>
  </collision>
</link>

<link name="nema17_Mirror__1">
  <inertial>
    <origin rpy="0 0 0" xyz="0.0033427367952116732 6.3450027137950304e-06 0.021180135259303026"/>
    <mass value="0.1838412954712099"/>
    <inertia ixx="5.3e-05" ixy="0.0" ixz="-0.0" iyy="5.2e-05" iyz="0.0" izz="5.2e-05"/>
  </inertial>
  <visual>
    <origin rpy="0 0 0" xyz="0.099 -3.4e-05 -0.003"/>
    <geometry>
      <mesh filename="package://ppp_description/meshes/nema17_Mirror__1.stl" scale="0.001 0.001 0.001"/>
    </geometry>
    <material name="silver"/>
  </visual>
  <collision>
    <origin rpy="0 0 0" xyz="0.099 -3.4e-05 -0.003"/>
    <geometry>
      <mesh filename="package://ppp_description/meshes/nema17_Mirror__1.stl" scale="0.001 0.001 0.001"/>
    </geometry>
  </collision>
</link>

<link name="12GAN20__1__1">
  <inertial>
    <origin rpy="0 0 0" xyz="-3.292631452073147e-06 -6.626992531399978e-07 0.01185787133707267"/>
    <mass value="0.023492103087793172"/>
    <inertia ixx="2e-06" ixy="0.0" ixz="-0.0" iyy="1e-06" iyz="0.0" izz="0.0"/>
  </inertial>
  <visual>
    <origin rpy="0 0 0" xyz="0.113402 -0.08196 -0.001"/>
    <geometry>
      <mesh filename="package://ppp_description/meshes/12GAN20__1__1.stl" scale="0.001 0.001 0.001"/>
    </geometry>
    <material name="silver"/>
  </visual>
  <collision>
    <origin rpy="0 0 0" xyz="0.113402 -0.08196 -0.001"/>
    <geometry>
      <mesh filename="package://ppp_description/meshes/12GAN20__1__1.stl" scale="0.001 0.001 0.001"/>
    </geometry>
  </collision>
</link>

<link name="brush_1">
  <inertial>
    <origin rpy="0 0 0" xyz="-7.733309837359981e-07 3.2946715564086126e-08 -0.0022204199308318265"/>
    <mass value="0.014937067448072668"/>
    <inertia ixx="1e-06" ixy="-0.0" ixz="0.0" iyy="1e-06" iyz="-0.0" izz="2e-06"/>
  </inertial>
  <visual>
    <origin rpy="0 0 0" xyz="0.113412 -0.081962 0.001"/>
    <geometry>
      <mesh filename="package://ppp_description/meshes/brush_1.stl" scale="0.001 0.001 0.001"/>
    </geometry>
    <material name="silver"/>
  </visual>
  <collision>
    <origin rpy="0 0 0" xyz="0.113412 -0.081962 0.001"/>
    <geometry>
      <mesh filename="package://ppp_description/meshes/brush_1.stl" scale="0.001 0.001 0.001"/>
    </geometry>
  </collision>
</link>

<link name="brush_Mirror__1">
  <inertial>
    <origin rpy="0 0 0" xyz="-5.614420229005379e-07 -1.2298749614975124e-06 -0.0022204199308317844"/>
    <mass value="0.014937067448072664"/>
    <inertia ixx="1e-06" ixy="-0.0" ixz="0.0" iyy="1e-06" iyz="0.0" izz="2e-06"/>
  </inertial>
  <visual>
    <origin rpy="0 0 0" xyz="-0.113393 -0.081958 0.001"/>
    <geometry>
      <mesh filename="package://ppp_description/meshes/brush_Mirror__1.stl" scale="0.001 0.001 0.001"/>
    </geometry>
    <material name="silver"/>
  </visual>
  <collision>
    <origin rpy="0 0 0" xyz="-0.113393 -0.081958 0.001"/>
    <geometry>
      <mesh filename="package://ppp_description/meshes/brush_Mirror__1.stl" scale="0.001 0.001 0.001"/>
    </geometry>
  </collision>
</link>

<link name="12GAN20__1__Mirror__1">
  <inertial>
    <origin rpy="0 0 0" xyz="-7.3554193489588915e-06 -2.6912147267910136e-06 0.011857871337072678"/>
    <mass value="0.02349210308779317"/>
    <inertia ixx="2e-06" ixy="-0.0" ixz="0.0" iyy="1e-06" iyz="0.0" izz="0.0"/>
  </inertial>
  <visual>
    <origin rpy="0 0 0" xyz="-0.113393 -0.081958 -0.001"/>
    <geometry>
      <mesh filename="package://ppp_description/meshes/12GAN20__1__Mirror__1.stl" scale="0.001 0.001 0.001"/>
    </geometry>
    <material name="silver"/>
  </visual>
  <collision>
    <origin rpy="0 0 0" xyz="-0.113393 -0.081958 -0.001"/>
    <geometry>
      <mesh filename="package://ppp_description/meshes/12GAN20__1__Mirror__1.stl" scale="0.001 0.001 0.001"/>
    </geometry>
  </collision>
</link>

<link name="FW_baise_1">
  <inertial>
    <origin rpy="0 0 0" xyz="0.014149999999964021 -0.011650110353972745 -0.0014374507094137914"/>
    <mass value="0.0061871055650105375"/>
    <inertia ixx="0.0" ixy="0.0" ixz="-0.0" iyy="0.0" iyz="-0.0" izz="1e-06"/>
  </inertial>
  <visual>
    <origin rpy="0 0 0" xyz="0.014 -0.117931 -0.022"/>
    <geometry>
      <mesh filename="package://ppp_description/meshes/FW_baise_1.stl" scale="0.001 0.001 0.001"/>
    </geometry>
    <material name="silver"/>
  </visual>
  <collision>
    <origin rpy="0 0 0" xyz="0.014 -0.117931 -0.022"/>
    <geometry>
      <mesh filename="package://ppp_description/meshes/FW_baise_1.stl" scale="0.001 0.001 0.001"/>
    </geometry>
  </collision>
</link>

<link name="wheel__1__1">
  <inertial>
    <origin rpy="0 0 0" xyz="1.872807464664561e-14 -1.1035397273762015e-07 4.466912950640278e-17"/>
    <mass value="0.0030771108424005812"/>
    <inertia ixx="0.0" ixy="0.0" ixz="-0.0" iyy="0.0" iyz="-0.0" izz="0.0"/>
  </inertial>
  <visual>
    <origin rpy="0 0 0" xyz="-0.00815 -0.106281 -0.0004"/>
    <geometry>
      <mesh filename="package://ppp_description/meshes/wheel__1__1.stl" scale="0.001 0.001 0.001"/>
    </geometry>
    <material name="silver"/>
  </visual>
  <collision>
    <origin rpy="0 0 0" xyz="-0.00815 -0.106281 -0.0004"/>
    <geometry>
      <mesh filename="package://ppp_description/meshes/wheel__1__1.stl" scale="0.001 0.001 0.001"/>
    </geometry>
  </collision>
</link>

<link name="axis_1">
  <inertial>
    <origin rpy="0 0 0" xyz="0.03303899999968629 -1.1035397272374237e-07 -0.035509999999999944"/>
    <mass value="0.0043107049436968805"/>
    <inertia ixx="0.0" ixy="0.0" ixz="0.0" iyy="0.0" iyz="0.0" izz="0.0"/>
  </inertial>
  <visual>
    <origin rpy="0 0 0" xyz="0.024889 -0.106281 -0.03591"/>
    <geometry>
      <mesh filename="package://ppp_description/meshes/axis_1.stl" scale="0.001 0.001 0.001"/>
    </geometry>
    <material name="silver"/>
  </visual>
  <collision>
    <origin rpy="0 0 0" xyz="0.024889 -0.106281 -0.03591"/>
    <geometry>
      <mesh filename="package://ppp_description/meshes/axis_1.stl" scale="0.001 0.001 0.001"/>
    </geometry>
  </collision>
</link>

<link name="holder_1">
  <inertial>
    <origin rpy="0 0 0" xyz="0.0011550098836461376 -3.867842181329295e-06 -0.0024145150891157104"/>
    <mass value="0.006489971019909515"/>
    <inertia ixx="1e-06" ixy="-0.0" ixz="0.0" iyy="0.0" iyz="-0.0" izz="1e-06"/>
  </inertial>
  <visual>
    <origin rpy="0 0 0" xyz="-0.00015 -0.106281 -0.0145"/>
    <geometry>
      <mesh filename="package://ppp_description/meshes/holder_1.stl" scale="0.001 0.001 0.001"/>
    </geometry>
    <material name="silver"/>
  </visual>
  <collision>
    <origin rpy="0 0 0" xyz="-0.00015 -0.106281 -0.0145"/>
    <geometry>
      <mesh filename="package://ppp_description/meshes/holder_1.stl" scale="0.001 0.001 0.001"/>
    </geometry>
  </collision>
</link>

<link name="axis_main_1">
  <inertial>
    <origin rpy="0 0 0" xyz="4.181978385548596e-13 -1.1035397275149794e-07 -0.003749999999999993"/>
    <mass value="0.003193114773108801"/>
    <inertia ixx="0.0" ixy="-0.0" ixz="-0.0" iyy="0.0" iyz="-0.0" izz="0.0"/>
  </inertial>
  <visual>
    <origin rpy="0 0 0" xyz="-0.00015 -0.106281 -0.022"/>
    <geometry>
      <mesh filename="package://ppp_description/meshes/axis_main_1.stl" scale="0.001 0.001 0.001"/>
    </geometry>
    <material name="silver"/>
  </visual>
  <collision>
    <origin rpy="0 0 0" xyz="-0.00015 -0.106281 -0.022"/>
    <geometry>
      <mesh filename="package://ppp_description/meshes/axis_main_1.stl" scale="0.001 0.001 0.001"/>
    </geometry>
  </collision>
</link>

<link name="IMU_1">
  <inertial>
    <origin rpy="0 0 0" xyz="2.3440450969136606e-16 4.815371235089572e-07 0.008500000000000056"/>
    <mass value="0.014012250000000002"/>
    <inertia ixx="0.0" ixy="-0.0" ixz="-0.0" iyy="1e-06" iyz="0.0" izz="1e-06"/>
  </inertial>
  <visual>
    <origin rpy="0 0 0" xyz="0.001 -0.14314 -0.033"/>
    <geometry>
      <mesh filename="package://ppp_description/meshes/IMU_1.stl" scale="0.001 0.001 0.001"/>
    </geometry>
    <material name="silver"/>
  </visual>
  <collision>
    <origin rpy="0 0 0" xyz="0.001 -0.14314 -0.033"/>
    <geometry>
      <mesh filename="package://ppp_description/meshes/IMU_1.stl" scale="0.001 0.001 0.001"/>
    </geometry>
  </collision>
</link>

<link name="forward_top_1_1">
  <inertial>
    <origin rpy="0 0 0" xyz="0.06502199144873529 -0.09472380566284748 0.0004895173930853369"/>
    <mass value="0.48710215659029577"/>
    <inertia ixx="0.00099" ixy="0.000235" ixz="1e-06" iyy="0.000784" iyz="-1e-06" izz="0.001773"/>
  </inertial>
  <visual>
    <origin rpy="0 0 0" xyz="0.0 -0.149 -0.11"/>
    <geometry>
      <mesh filename="package://ppp_description/meshes/forward_top_1_1.stl" scale="0.001 0.001 0.001"/>
    </geometry>
    <material name="silver"/>
  </visual>
  <collision>
    <origin rpy="0 0 0" xyz="0.0 -0.149 -0.11"/>
    <geometry>
      <mesh filename="package://ppp_description/meshes/forward_top_1_1.stl" scale="0.001 0.001 0.001"/>
    </geometry>
  </collision>
</link>


<link name="forward_top_1_Mirror__1">
  <inertial>
    <origin rpy="0 0 0" xyz="0.07845779784140774 0.07359181457392162 0.0004895171912021601"/>
    <mass value="0.48710223650351714"/>
    <inertia ixx="0.00099" ixy="-0.000234" ixz="-1e-06" iyy="0.000784" iyz="-1e-06" izz="0.001773"/>
  </inertial>
  <visual>
    <origin rpy="0 0 0" xyz="0.14353 0.01936 -0.11"/>
    <geometry>
      <mesh filename="package://ppp_description/meshes/forward_top_1_Mirror__1.stl" scale="0.001 0.001 0.001"/>
    </geometry>
    <material name="silver"/>
  </visual>
  <collision>
    <origin rpy="0 0 0" xyz="0.14353 0.01936 -0.11"/>
    <geometry>
      <mesh filename="package://ppp_description/meshes/forward_top_1_Mirror__1.stl" scale="0.001 0.001 0.001"/>
    </geometry>
  </collision>
</link>

<link name="back_top_1">
  <inertial>
    <origin rpy="0 0 0" xyz="0.07365321533839897 -0.06983833949014678 -0.0010887199497685018"/>
    <mass value="0.23560428740017997"/>
    <inertia ixx="0.00038" ixy="0.000345" ixz="1.8e-05" iyy="0.000537" iyz="-1.3e-05" izz="0.000907"/>
  </inertial>
  <visual>
    <origin rpy="0 0 0" xyz="0.14353 0.01936 -0.11"/>
    <geometry>
      <mesh filename="package://ppp_description/meshes/back_top_1.stl" scale="0.001 0.001 0.001"/>
    </geometry>
    <material name="silver"/>
  </visual>
  <collision>
    <origin rpy="0 0 0" xyz="0.14353 0.01936 -0.11"/>
    <geometry>
      <mesh filename="package://ppp_description/meshes/back_top_1.stl" scale="0.001 0.001 0.001"/>
    </geometry>
  </collision>
</link>

<link name="back_top2_1">
  <inertial>
    <origin rpy="0 0 0" xyz="-0.05499670719604889 -0.05870846160678311 0.0004968868769273244"/>
    <mass value="0.18961170684744505"/>
    <inertia ixx="0.000249" ixy="-0.000153" ixz="1e-06" iyy="0.000183" iyz="1e-06" izz="0.000432"/>
  </inertial>
  <visual>
    <origin rpy="0 0 0" xyz="-0.14353 0.01936 -0.11"/>
    <geometry>
      <mesh filename="package://ppp_description/meshes/back_top2_1.stl" scale="0.001 0.001 0.001"/>
    </geometry>
    <material name="silver"/>
  </visual>
  <collision>
    <origin rpy="0 0 0" xyz="-0.14353 0.01936 -0.11"/>
    <geometry>
      <mesh filename="package://ppp_description/meshes/back_top2_1.stl" scale="0.001 0.001 0.001"/>
    </geometry>
  </collision>
</link>

<link name="Lidar_1">
  <inertial>
    <origin rpy="0 0 0" xyz="1.0794814273332957e-07 2.1384410779645702e-07 0.03500000000000002"/>
    <mass value="0.0"/>
    <inertia ixx="0.0" ixy="0.0" ixz="-0.0" iyy="0.0" iyz="-0.0" izz="0.0"/>
  </inertial>
  <visual>
    <origin rpy="0 0 0" xyz="7.9e-05 -0.09632 -0.112"/>
    <geometry>
      <mesh filename="package://ppp_description/meshes/Lidar_1.stl" scale="0.001 0.001 0.001"/>
    </geometry>
    <material name="silver"/>
  </visual>
  <collision>
    <origin rpy="0 0 0" xyz="7.9e-05 -0.09632 -0.112"/>
    <geometry>
      <mesh filename="package://ppp_description/meshes/Lidar_1.stl" scale="0.001 0.001 0.001"/>
    </geometry>
  </collision>
</link>


<joint name="Rev1" type="continuous">
  <origin rpy="0 0 0" xyz="0.04585 0.0 0.021125"/>
  <parent link="nema17_1"/>
  <child link="wheel_1"/>
  <axis xyz="1.0 0.0 -0.0"/>
  <limit effort="10" velocity="100"/>
</joint>

<joint name="Rev4" type="continuous">
  <origin rpy="0 0 0" xyz="-0.02285 -3.7e-05 0.021125"/>
  <parent link="nema17_Mirror__1"/>
  <child link="wheel_Mirror__1"/>
  <axis xyz="-0.999999 -0.001615 0.0"/>
</joint>

<joint name="Rigid5" type="fixed">
  <origin rpy="0 0 0" xyz="0.150568 0.013 0.08983"/>
  <parent link="base_link"/>
  <child link="sonyc_1"/>
</joint>

<joint name="Rigid6" type="fixed">
  <origin rpy="0 0 3" xyz="-0.150568 -0.013 0.08983"/>
  <parent link="base_link"/>
  <child link="sonyc_Mirror__1"/>
</joint>

<joint name="Rigid7" type="fixed">
  <origin rpy="0 0 1.5" xyz="0.012977 0.154921 0.06983"/>
  <parent link="base_link"/>
  <child link="sonyc__1__1"/>
</joint>

<joint name="Rigid8" type="fixed">
  <origin rpy="0 0 0" xyz="0.098409 0.0 0.003"/>
  <parent link="base_link"/>
  <child link="nema17_1"/>
</joint>

<joint name="Rigid9" type="fixed">
  <origin rpy="0 0 0" xyz="-0.099 3.4e-05 0.003"/>
  <parent link="base_link"/>
  <child link="nema17_Mirror__1"/>
</joint>

<joint name="Rigid13" type="fixed">
  <origin rpy="0 0 0" xyz="-0.113402 0.08196 0.001"/>
  <parent link="base_link"/>
  <child link="12GAN20__1__1"/>
</joint>

<joint name="Rev14" type="continuous">
  <origin rpy="0 0 0" xyz="-1e-05 2e-06 -0.002"/>
  <parent link="12GAN20__1__1"/>
  <child link="brush_1"/>
  <axis xyz="0.0 -0.0 -1.0"/>
</joint>

<joint name="Rev15" type="continuous">
  <origin rpy="0 0 0" xyz="0.0 0.0 -0.002"/>
  <parent link="12GAN20__1__Mirror__1"/>
  <child link="brush_Mirror__1"/>
  <axis xyz="-0.0 -0.0 -1.0"/>
</joint>

<joint name="Rigid16" type="fixed">
  <origin rpy="0 0 0" xyz="0.113393 0.081958 0.001"/>
  <parent link="base_link"/>
  <child link="12GAN20__1__Mirror__1"/>
</joint>

<joint name="Rigid22" type="fixed">
  <origin rpy="0 0 0" xyz="-0.014 0.117931 0.022"/>
  <parent link="base_link"/>
  <child link="FW_baise_1"/>
</joint>

<joint name="Rev26" type="continuous">
  <origin rpy="0 0 0" xyz="0.033039 0.0 -0.03551"/>
  <parent link="axis_1"/>
  <child link="wheel__1__1"/>
  <axis xyz="-0.0 -1.0 -0.0"/>
</joint>

<joint name="Rev27" type="continuous">
  <origin rpy="0 0 0" xyz="-0.025039 0.0 0.02141"/>
  <parent link="holder_1"/>
  <child link="axis_1"/>
  <axis xyz="0.0 1.0 0.0"/>
</joint>

<joint name="Rev28" type="continuous">
  <origin rpy="0 0 0" xyz="0.0 0.0 -0.0075"/>
  <parent link="axis_main_1"/>
  <child link="holder_1"/>
  <axis xyz="-0.0 0.0 -1.0"/>
</joint>

<joint name="Rev29" type="continuous">
  <origin rpy="0 0 0" xyz="0.01415 -0.01165 0.0"/>
  <parent link="FW_baise_1"/>
  <child link="axis_main_1"/>
  <axis xyz="0.0 -0.0 -1.0"/>
</joint>

<joint name="IMU_TO_MAIN" type="fixed">
  <origin rpy="0 0 0" xyz="-0.001 0.14314 0.033"/>
  <parent link="base_link"/>
  <child link="IMU_1"/>
</joint>



<joint name="Rigid21" type="fixed">
  <origin rpy="0 0 0" xyz="0.0 0.149 0.11"/>
  <parent link="base_link"/>
  <child link="forward_top_1_1"/>
</joint>

<joint name="Rigid22_1" type="fixed">
  <origin rpy="0 0 0" xyz="-0.14353 -0.01936 0.11"/>
  <parent link="base_link"/>
  <child link="forward_top_1_Mirror__1"/>
</joint>

<joint name="Rigid23" type="fixed">
  <origin rpy="0 0 0" xyz="-0.14353 -0.01936 0.11"/>
  <parent link="base_link"/>
  <child link="back_top_1"/>
</joint>

<joint name="Rigid24" type="fixed">
  <origin rpy="0 0 0" xyz="0.14353 -0.01936 0.11"/>
  <parent link="base_link"/>
  <child link="back_top2_1"/>
</joint>

<joint name="Rigid25" type="fixed">
  <origin rpy="0 0 0" xyz="0.143451 0.11568 0.002"/>
  <parent link="forward_top_1_Mirror__1"/>
  <child link="Lidar_1"/>
</joint>


</robot>
